<?xml version="1.0"?>
<robot name="duckiefloat">
  <link name="base_link">
    <visual>
      <geometry>
        <box size="0.25 .16 .05"/>
    </geometry>
    <origin rpy="0 0 1.57075" xyz="0 0 0"/>
    <material name="blue">
        <color rgba="0 0 .8 1"/>
    </material>
    </visual>
  </link>

  <link name="velodyne">
    <visual>
      <geometry>
        <cylinder length=".02" radius="0.025"/>
      </geometry>
      <material name="black">
        <color rgba="0 0 0 1"/>
      </material>
    </visual>
  </link>
  <joint name="velodyne" type="continuous">
    <axis xyz="0 0 1"/>
    <parent link="base_link"/>
    <child link="velodyne"/>
    <origin rpy="0 0 0" xyz="0 0 0.25"/>
    <limit effort="100" velocity="100"/>
    <joint_properties damping="0.0" friction="0.0"/>
  </joint>

  <link name="imu">
    <visual>
      <geometry>
        <cylinder length=".02" radius="0.025"/>
      </geometry>
      <material name="black">
        <color rgba="0 0 0 1"/>
      </material>
    </visual>
  </link>
  <joint name="imu" type="continuous">
    <axis xyz="0 0 1"/>
    <parent link="base_link"/>
    <child link="imu"/>
    <origin rpy="0 0 0" xyz="0.1 0.04 0"/>
    <limit effort="100" velocity="100"/>
    <joint_properties damping="0.0" friction="0.0"/>
  </joint>


</robot>
